
ERROR:root:Database user lookup failed: cannot access free variable 'User' where it is not associated with a value in enclosing scope
[2025-10-21 00:09:47,149] ERROR in app: Exception on /auth/login [POST]
Traceback (most recent call last):
  File "/opt/venv/lib/python3.11/site-packages/flask/app.py", line 1473, in wsgi_app
    response = self.full_dispatch_request()
         ^^^^^^^^^^^^^^^^^^^^^^^^^^^^^
               ^^^^^^^^^^^^^^^^^^^^^^^^^^^^
  File "/opt/venv/lib/python3.11/site-packages/flask/app.py", line 882, in full_dispatch_request
    rv = self.handle_user_exception(e)
  File "/opt/venv/lib/python3.11/site-packages/flask/app.py", line 880, in full_dispatch_request
    rv = self.dispatch_request()
         ^^^^^^^^^^^^^^^^^^^^^^^
  File "/opt/venv/lib/python3.11/site-packages/flask/app.py", line 865, in dispatch_request
    return self.ensure_sync(self.view_functions[rule.endpoint])(**view_args)  # type: ignore[no-any-return]
           ^^^^^^^^^^^^^^^^^^^^^^^^^^^^^^^^^^^^^^^^^^^^^^^^^^^^^^^^^^^^^^^^^
  File "/app/photovault/routes/auth.py", line 71, in login
    user = safe_db_query(
           ^^^^^^^^^^^^^^
  File "/app/photovault/utils/__init__.py", line 82, in safe_db_query
    return execute_query()
           ^^^^^^^^^^^^^^^
    rv = self.handle_user_exception(e)
NameError: cannot access free variable 'User' where it is not associated with a value in enclosing scope
  File "/app/photovault/utils/__init__.py", line 68, in wrapper
         ^^^^^^^^^^^^^^^^^^^^^^^^^^^^^
2025-10-21 00:09:47,149 ERROR: Exception on /auth/login [POST] [in /opt/venv/lib/python3.11/site-packages/flask/app.py:838]
    response = self.full_dispatch_request()
    raise e
  File "/opt/venv/lib/python3.11/site-packages/flask/app.py", line 880, in full_dispatch_request
Traceback (most recent call last):
               ^^^^^^^^^^^^^^^^^^^^^^^^^^^^
  File "/app/photovault/utils/__init__.py", line 28, in wrapper
  File "/opt/venv/lib/python3.11/site-packages/flask/app.py", line 1473, in wsgi_app
  File "/opt/venv/lib/python3.11/site-packages/flask/app.py", line 882, in full_dispatch_request
    return func(*args, **kwargs)
           ^^^^^^^^^^^^^^^^^^^^^
  File "/app/photovault/utils/__init__.py", line 79, in execute_query
    return query_func()
           ^^^^^^^^^^^^
  File "/app/photovault/routes/auth.py", line 67, in query_user
    return User.query.filter(
           ^^^^
    return query_func()
    rv = self.dispatch_request()
           ^^^^^^^^^^^^
         ^^^^^^^^^^^^^^^^^^^^^^^
  File "/app/photovault/routes/auth.py", line 67, in query_user
  File "/opt/venv/lib/python3.11/site-packages/flask/app.py", line 865, in dispatch_request
    return User.query.filter(
           ^^^^
    return self.ensure_sync(self.view_functions[rule.endpoint])(**view_args)  # type: ignore[no-any-return]
NameError: cannot access free variable 'User' where it is not associated with a value in enclosing scope
           ^^^^^^^^^^^^^^^^^^^^^^^^^^^^^^^^^^^^^^^^^^^^^^^^^^^^^^^^^^^^^^^^^
  File "/app/photovault/routes/auth.py", line 71, in login
    user = safe_db_query(
           ^^^^^^^^^^^^^^
  File "/app/photovault/utils/__init__.py", line 82, in safe_db_query
    return execute_query()
           ^^^^^^^^^^^^^^^
  File "/app/photovault/utils/__init__.py", line 68, in wrapper
    raise e
  File "/app/photovault/utils/__init__.py", line 28, in wrapper
    return func(*args, **kwargs)
           ^^^^^^^^^^^^^^^^^^^^^
  File "/app/photovault/utils/__init__.py", line 79, in execute_query
           ^^^^^^^^^^^^^^^^^^^^^^^^^^^^^^^^^^^^^^^^^^^^^^^^^^^^^^^^^^^^^^^^^
2025-10-21 00:09:47,149 ERROR: Exception on /auth/login [POST] [in /opt/venv/lib/python3.11/site-packages/flask/app.py:838]
  File "/app/photovault/routes/auth.py", line 71, in login
Traceback (most recent call last):
  File "/opt/venv/lib/python3.11/site-packages/flask/app.py", line 882, in full_dispatch_request
    user = safe_db_query(
  File "/opt/venv/lib/python3.11/site-packages/flask/app.py", line 1473, in wsgi_app
    rv = self.handle_user_exception(e)
           ^^^^^^^^^^^^^^
    response = self.full_dispatch_request()
         ^^^^^^^^^^^^^^^^^^^^^^^^^^^^^
               ^^^^^^^^^^^^^^^^^^^^^^^^^^^^
  File "/app/photovault/utils/__init__.py", line 82, in safe_db_query
  File "/opt/venv/lib/python3.11/site-packages/flask/app.py", line 880, in full_dispatch_request
    return execute_query()
    rv = self.dispatch_request()
           ^^^^^^^^^^^^^^^
         ^^^^^^^^^^^^^^^^^^^^^^^
  File "/opt/venv/lib/python3.11/site-packages/flask/app.py", line 865, in dispatch_request
    return self.ensure_sync(self.view_functions[rule.endpoint])(**view_args)  # type: ignore[no-any-return]
  File "/app/photovault/utils/__init__.py", line 68, in wrapper
    return User.query.filter(
    rv = self.handle_user_exception(e)
    raise e
         ^^^^^^^^^^^^^^^^^^^^^^^^^^^^^
           ^^^^
NameError: cannot access free variable 'User' where it is not associated with a value in enclosing scope
  File "/opt/venv/lib/python3.11/site-packages/flask/app.py", line 880, in full_dispatch_request
  File "/app/photovault/utils/__init__.py", line 28, in wrapper
ERROR:photovault:Exception on /auth/login [POST]
    rv = self.dispatch_request()
    return func(*args, **kwargs)
    response = self.full_dispatch_request()
Traceback (most recent call last):
           ^^^^^^^^^^^^^^^^^^^^^
  File "/opt/venv/lib/python3.11/site-packages/flask/app.py", line 1473, in wsgi_app
