  File "/opt/venv/lib/python3.11/site-packages/flask/app.py", line 1253, in preprocess_request
    rv = self.ensure_sync(before_func)()
         ^^^^^^^^^^^^^^^^^^^^^^^^^^^^^^^
  File "/app/photovault/__init__.py", line 355, in enforce_subscription
    ).first()
      ^^^^^^^
  File "/opt/venv/lib/python3.11/site-packages/sqlalchemy/orm/query.py", line 2748, in first
    return self.limit(1)._iter().first()  # type: ignore
           ^^^^^^^^^^^^^^^^^^^^^
  File "/opt/venv/lib/python3.11/site-packages/sqlalchemy/orm/query.py", line 2847, in _iter
    result: Union[ScalarResult[_T], Result[_T]] = self.session.execute(
                                                  ^^^^^^^^^^^^^^^^^^^^^
  File "/opt/venv/lib/python3.11/site-packages/sqlalchemy/orm/session.py", line 2308, in execute
  File "/opt/venv/lib/python3.11/site-packages/flask/app.py", line 1473, in wsgi_app
    return self._execute_internal(
    response = self.full_dispatch_request()
           ^^^^^^^^^^^^^^^^^^^^^^^
  File "/opt/venv/lib/python3.11/site-packages/sqlalchemy/orm/session.py", line 2190, in _execute_internal
    result: Result[Any] = compile_state_cls.orm_execute_statement(
                          ^^^^^^^^^^^^^^^^^^^^^^^^^^^^^^^^^^^^^^^^
  File "/opt/venv/liERROR:photovault:Exception on / [GET]
Traceback (most recent call last):
  File "/opt/venv/lib/python3.11/site-packages/sqlalchemy/engine/base.py", line 1969, in _exec_single_context
    self.dialect.do_execute(
  File "/opt/venv/lib/python3.11/site-packages/sqlalchemy/engine/default.py", line 922, in do_execute
    cursor.execute(statement, parameters)
psycopg2.errors.UndefinedColumn: column user_subscription.ai_enhancements_used does not exist
LINE 1: ...cancel_reason AS user_subscription_cancel_reason, user_subsc...
                                                             ^
The above exception was the direct cause of the following exception:
Traceback (most recent call last):
               ^^^^^^^^^^^^^^^^^^^^^^^^^^^^
  File "/opt/venv/lib/python3.11/site-packages/flask/app.py", line 882, in full_dispatch_request
    rv = self.handle_user_exception(e)
         ^^^^^^^^^^^^^^^^^^^^^^^^^^^^^
  File "/opt/venv/lib/python3.11/site-packages/flask/app.py", line 878, in full_dispatch_request
    rv = self.preprocess_request()
         ^^^^^^^^^^^^^^^^^^^^^^^^^
  File "/opt/venv/lib/python3.11/site-packages/flask/app.py", line 1253, in preprocess_request
    rv = self.ensure_sync(before_func)()
         ^^^^^^^^^^^^^^^^^^^^^^^^^^^^^^^
  File "/app/photovault/__init__.py", line 355, in enforce_subscription
    ).first()
      ^^^^^^^
  File "/opt/venv/lib/python3.11/site-packages/sqlalchemy/orm/query.py", line 2748, in first
    return self.limit(1)._iter().first()  # type: ignore
           ^^^^^^^^^^^^^^^^^^^^^
  File "/opt/venv/lib/python3.11/site-packages/sqlalchemy/orm/query.py", line 2847, in _iter
    result: Union[ScalarResult[_T], Result[_T]] = self.session.execute(
                                                  ^^^^^^^^^^^^^^^^^^^^^
  File "/opt/venv/lib/python3.11/site-packages/sqlalchemy/orm/session.py", line 2308, in execute
    return self._execute_internal(
  File "/opt/venv/lib/python3.11/site-packages/sqlalchemy/sql/elements.py", line 517, in _execute_on_connection
           ^^^^^^^^^^^^^^^^^^^^^^^
    return connection._execute_clauseelement(
  File "/opt/venv/lib/python3.11/site-packages/sqlalchemy/orm/session.py", line 2190, in _execute_internal
           ^^^^^^^^^^^^^^^^^^^^^^^^^^^^^^^^^^
  File "/opt/venv/lib/python3.11/site-packages/sqlalchemy/engine/base.py", line 1639, in _execute_clauseelement
    result: Result[Any] = compile_state_cls.orm_execute_statement(
    ret = self._execute_context(
          ^^^^^^^^^^^^^^^^^^^^^^
                          ^^^^^^^^^^^^^^^^^^^^^^^^^^^^^^^^^^^^^^^^
  File "/opt/venv/lib/python3.11/site-packages/sqlalchemy/engine/base.py", line 1848, in _execute_context
  File "/opt/venv/lib/python3.11/site-packages/sqlalchemy/orm/context.py", line 293, in orm_execute_statement
    return self._exec_single_context(
    result = conn.execute(
           ^^^^^^^^^^^^^^^^^^^^^^^^^^
             ^^^^^^^^^^^^^
  File "/opt/venv/lib/python3.11/site-packages/sqlalchemy/engine/base.py", line 1416, in execute
    return meth(
           ^^^^^
  File "/opt/venv/lib/python3.11/site-packages/sqlalchemy/engine/base.py", line 1988, in _exec_single_context
    self._handle_dbapi_exception(
  File "/opt/venv/lib/python3.11/site-packages/sqlalchemy/engine/base.py", line 2344, in _handle_dbapi_exception
    raise sqlalchemy_exception.with_traceback(exc_info[2]) from e
  File "/opt/venv/lib/python3.11/site-packages/sqlalchemy/engine/base.py", line 1969, in _exec_single_context
    self.dialect.do_execute(
  File "/opt/venv/lib/python3.11/site-packages/sqlalchemy/engine/default.py", line 922, in do_execute
    cursor.execute(statement, parameters)
sqlalchemy.exc.ProgrammingError: (psycopg2.errors.UndefinedColumn) column user_subscription.ai_enhancements_used does not exist
LINE 1: ...cancel_reason AS user_subscription_cancel_reason, user_subsc...
                                                             ^
[SQL: SELECT user_subscription.id AS user_subscription_id, user_subscription.user_id AS user_subscription_user_id, user_subscription.plan_id AS user_subscription_plan_id, user_subscription.status AS user_subscription_status, user_subscription.stripe_subscription_id AS user_subscription_stripe_subscription_id, user_subscription.stripe_customer_id AS user_subscription_stripe_customer_id, user_subscription.start_date AS user_subscription_start_date, user_subscription.current_period_start AS user_subscription_current_period_start, user_subscription.current_period_end AS user_subscription_current_period_end, user_subscription.canceled_at AS user_subscription_canceled_at, user_subscription.ended_at AS user_subscription_ended_at, user_subscription.trial_end AS user_subscription_trial_end, user_subscription.last_payment_date AS user_subscription_last_payment_date, user_subscription.next_billing_date AS user_subscription_next_billing_date, user_subscription.cancel_at_period_end AS user_subscription_cancel_at_period_end, user_subscription.cancel_reason AS user_subscription_cancel_reason, user_subscription.ai_enhancements_used AS user_subscription_ai_enhancements_used, user_subscription.ai_enhancements_reset_date AS user_subscription_ai_enhancements_reset_date, user_subscription.created_at AS user_subscription_created_at, user_subscription.updated_at AS user_subscription_updated_at 
    return self._exec_single_context(
           ^^^^^^^^^^^^^^^^^^^^^^^^^^
  File "/opt/venv/lib/python3.11/site-packages/sqlalchemy/engine/base.py", line 1988, in _exec_single_context
FROM user_subscription 
WHERE user_subscription.user_id = %(user_id_1)s AND user_subscription.status = %(status_1)s 
 LIMIT %(param_1)s]
[parameters: {'user_id_1': 2, 'status_1': 'active', 'param_1': 1}]
(Background on this error at: https://sqlalche.me/e/20/f405)
b/python3.11/site-packages/sqlalchemy/orm/context.py", line 293, in orm_execute_statement
    result = conn.execute(
             ^^^^^^^^^^^^^
  File "/opt/venv/lib/python3.11/site-packages/sqlalchemy/engine/base.py", line 1416, in execute
    return meth(
           ^^^^^
  File "/opt/venv/lib/python3.11/site-packages/sqlalchemy/sql/elements.py", line 517, in _execute_on_connection
    return connection._execute_clauseelement(
           ^^^^^^^^^^^^^^^^^^^^^^^^^^^^^^^^^^
  File "/opt/venv/lib/python3.11/site-packages/sqlalchemy/engine/base.py", line 1639, in _execute_clauseelement
    ret = self._execute_context(
          ^^^^^^^^^^^^^^^^^^^^^^
  File "/opt/venv/lib/python3.11/site-packages/sqlalchemy/engine/base.py", line 1848, in _execute_context
    self._handle_dbapi_exception(
  File "/opt/venv/lib/python3.11/site-packages/sqlalchemy/engine/base.py", line 2344, in _handle_dbapi_exception
    raise sqlalchemy_exception.with_traceback(exc_info[2]) from e
  File "/opt/venv/lib/python3.11/site-packages/sqlalchemy/engine/base.py", line 1969, in _exec_single_context
    self.dialect.do_execute(
