    return self.ensure_sync(self.view_functions[rule.endpoint])(**view_args)  # type: ignore[no-any-return]
           ^^^^^^^^^^^^^^^^^^^^^^^^^^^^^^^^^^^^^^^^^^^^^^^^^^^^^^^^^^^^^^^^^
  File "/app/photovault/utils/jwt_auth.py", line 72, in decorated
    return f(authenticated_user, *args, **kwargs)
           ^^^^^^^^^^^^^^^^^^^^^^^^^^^^^^^^^^^^^^
  File "/app/photovault/routes/gallery.py", line 599, in uploaded_file
    return send_file('static/img/placeholder.png', mimetype='image/png')
           ^^^^^^^^^^^^^^^^^^^^^^^^^^^^^^^^^^^^^^^^^^^^^^^^^^^^^^^^^^^^^
  File "/opt/venv/lib/python3.11/site-packages/flask/helpers.py", line 499, in send_file
    return werkzeug.utils.send_file(  # type: ignore[return-value]
           ^^^^^^^^^^^^^^^^^^^^^^^^^^^^^^^^^^^^^^^^^^^^^^^^^^^^^^^
  File "/opt/venv/lib/python3.11/site-packages/werkzeug/utils.py", line 428, in send_file
    stat = os.stat(path)
           ^^^^^^^^^^^^^
FileNotFoundError: [Errno 2] No such file or directory: '/app/photovault/static/img/placeholder.png'
2025-10-23 08:00:59,622 ERROR: Exception on /uploads/2/(f,"'int' object is not iterable") [GET] [in /opt/venv/lib/python3.11/site-packages/flask/app.py:838]
Traceback (most recent call last):
  File "/app/photovault/routes/gallery.py", line 394, in uploaded_file
    abort(404)
  File "/opt/venv/lib/python3.11/site-packages/flask/helpers.py", line 272, in abort
    current_app.aborter(code, *args, **kwargs)
  File "/opt/venv/lib/python3.11/site-packages/werkzeug/exceptions.py", line 863, in __call__
    raise self.mapping[code](*args, **kwargs)
werkzeug.exceptions.NotFound: 404 Not Found: The requested URL was not found on the server. If you entered the URL manually please check your spelling and try again.
During handling of the above exception, another exception occurred:
Traceback (most recent call last):
  File "/opt/venv/lib/python3.11/site-packages/flask/app.py", line 1473, in wsgi_app
    response = self.full_dispatch_request()
               ^^^^^^^^^^^^^^^^^^^^^^^^^^^^
  File "/opt/venv/lib/python3.11/site-packages/flask/app.py", line 882, in full_dispatch_request
    rv = self.handle_user_exception(e)
         ^^^^^^^^^^^^^^^^^^^^^^^^^^^^^
  File "/opt/venv/lib/python3.11/site-packages/flask/app.py", line 880, in full_dispatch_request
    rv = self.dispatch_request()
         ^^^^^^^^^^^^^^^^^^^^^^^
  File "/opt/venv/lib/python3.11/site-packages/flask/app.py", line 865, in dispatch_request
    return self.ensure_sync(self.view_functions[rule.endpoint])(**view_args)  # type: ignore[no-any-return]
           ^^^^^^^^^^^^^^^^^^^^^^^^^^^^^^^^^^^^^^^^^^^^^^^^^^^^^^^^^^^^^^^^^
  File "/app/photovault/utils/jwt_auth.py", line 72, in decorated
    return f(authenticated_user, *args, **kwargs)
           ^^^^^^^^^^^^^^^^^^^^^^^^^^^^^^^^^^^^^^
  File "/app/photovault/routes/gallery.py", line 599, in uploaded_file
    return send_file('static/img/placeholder.png', mimetype='image/png')
           ^^^^^^^^^^^^^^^^^^^^^^^^^^^^^^^^^^^^^^^^^^^^^^^^^^^^^^^^^^^^^
  File "/opt/venv/lib/python3.11/site-packages/flask/helpers.py", line 499, in send_file
    return werkzeug.utils.send_file(  # type: ignore[return-value]
           ^^^^^^^^^^^^^^^^^^^^^^^^^^^^^^^^^^^^^^^^^^^^^^^^^^^^^^^
  File "/opt/venv/lib/python3.11/site-packages/werkzeug/utils.py", line 428, in send_file
    stat = os.stat(path)
           ^^^^^^^^^^^^^
FileNotFoundError: [Errno 2] No such file or directory: '/app/photovault/static/img/placeholder.png'
2025-10-23 08:00:59,622 ERROR: Exception on /uploads/2/(f,"'int' object is not iterable") [GET] [in /opt/venv/lib/python3.11/site-packages/flask/app.py:838]
Traceback (most recent call last):
  File "/app/photovault/routes/gallery.py", line 394, in uploaded_file
    abort(404)
  File "/opt/venv/lib/python3.11/site-packages/flask/helpers.py", line 272, in abort
    current_app.aborter(code, *args, **kwargs)
  File "/opt/venv/lib/python3.11/site-packages/werkzeug/exceptions.py", line 863, in __call__
    raise self.mapping[code](*args, **kwargs)
werkzeug.exceptions.NotFound: 404 Not Found: The requested URL was not found on the server. If you entered the URL manually please check your spelling and try again.
During handling of the above exception, another exception occurred:
Traceback (most recent call last):
  File "/opt/venv/lib/python3.11/site-packages/flask/app.py", line 1473, in wsgi_app
    response = self.full_dispatch_request()
               ^^^^^^^^^^^^^^^^^^^^^^^^^^^^
  File "/opt/venv/lib/python3.11/site-packages/flask/app.py", line 882, in full_dispatch_request
    rv = self.handle_user_exception(e)
         ^^^^^^^^^^^^^^^^^^^^^^^^^^^^^
  File "/opt/venv/lib/python3.11/site-packages/flask/app.py", line 880, in full_dispatch_request
    rv = self.dispatch_request()
         ^^^^^^^^^^^^^^^^^^^^^^^
  File "/opt/venv/lib/python3.11/site-packages/flask/app.py", line 865, in dispatch_request
    return self.ensure_sync(self.view_functions[rule.endpoint])(**view_args)  # type: ignore[no-any-return]
           ^^^^^^^^^^^^^^^^^^^^^^^^^^^^^^^^^^^^^^^^^^^^^^^^^^^^^^^^^^^^^^^^^
  File "/app/photovault/utils/jwt_auth.py", line 72, in decorated
    abort(404)
  File "/opt/venv/lib/python3.11/site-packages/flask/helpers.py", line 272, in abort
    current_app.aborter(code, *args, **kwargs)
  File "/opt/venv/lib/python3.11/site-packages/werkzeug/exceptions.py", line 863, in __call__
    raise self.mapping[code](*args, **kwargs)
werkzeug.exceptions.NotFound: 404 Not Found: The requested URL was not found on the server. If you entered the URL manually please check your spelling and try again.
During handling of the above exception, another exception occurred:
Traceback (most recent call last):
  File "/opt/venv/lib/python3.11/site-packages/flask/app.py", line 1473, in wsgi_app
    response = self.full_dispatch_request()
               ^^^^^^^^^^^^^^^^^^^^^^^^^^^^
  File "/opt/venv/lib/python3.11/site-packages/flask/app.py", line 882, in full_dispatch_request
    rv = self.handle_user_exception(e)
         ^^^^^^^^^^^^^^^^^^^^^^^^^^^^^
  File "/opt/venv/lib/python3.11/site-packages/flask/app.py", line 880, in full_dispatch_request
    rv = self.dispatch_request()
         ^^^^^^^^^^^^^^^^^^^^^^^
  File "/opt/venv/lib/python3.11/site-packages/flask/app.py", line 865, in dispatch_request
    return self.ensure_sync(self.view_functions[rule.endpoint])(**view_args)  # type: ignore[no-any-return]
           ^^^^^^^^^^^^^^^^^^^^^^^^^^^^^^^^^^^^^^^^^^^^^^^^^^^^^^^^^^^^^^^^^
  File "/app/photovault/utils/jwt_auth.py", line 72, in decorated
    return f(authenticated_user, *args, **kwargs)
           ^^^^^^^^^^^^^^^^^^^^^^^^^^^^^^^^^^^^^^
  File "/app/photovault/routes/gallery.py", line 599, in uploaded_file
    return send_file('static/img/placeholder.png', mimetype='image/png')
           ^^^^^^^^^^^^^^^^^^^^^^^^^^^^^^^^^^^^^^^^^^^^^^^^^^^^^^^^^^^^^
  File "/opt/venv/lib/python3.11/site-packages/flask/helpers.py", line 499, in send_file
    return werkzeug.utils.send_file(  # type: ignore[return-value]
           ^^^^^^^^^^^^^^^^^^^^^^^^^^^^^^^^^^^^^^^^^^^^^^^^^^^^^^^
  File "/opt/venv/lib/python3.11/site-packages/werkzeug/utils.py", line 428, in send_file
    stat = os.stat(path)
           ^^^^^^^^^^^^^
FileNotFoundError: [Errno 2] No such file or directory: '/app/photovault/static/img/placeholder.png