ERROR:photovault:Exception on /admin/user/5 [GET]
Traceback (most recent call last):
  File "/opt/venv/lib/python3.11/site-packages/flask/app.py", line 1473, in wsgi_app
    response = self.full_dispatch_request()
               ^^^^^^^^^^^^^^^^^^^^^^^^^^^^
  File "/opt/venv/lib/python3.11/site-packages/flask/app.py", line 882, in full_dispatch_request
    rv = self.handle_user_exception(e)
         ^^^^^^^^^^^^^^^^^^^^^^^^^^^^^
  File "/opt/venv/lib/python3.11/site-packages/flask/app.py", line 880, in full_dispatch_request
  File "/app/photovault/routes/admin.py", line 169, in user_detail
    return render_template('admin/user_detail.html', user=user, photos=photos, user_stats=user_stats)
           ^^^^^^^^^^^^^^^^^^^^^^^^^^^^^^^^^^^^^^^^^^^^^^^^^^^^^^^^^^^^^^^^^^^^^^^^^^^^^^^^^^^^^^^^^^
  File "/opt/venv/lib/python3.11/site-packages/flask/templating.py", line 150, in render_template
    return _render(app, template, context)
    rv = self.dispatch_request()
           ^^^^^^^^^^^^^^^^^^^^^^^^^^^^^^^
         ^^^^^^^^^^^^^^^^^^^^^^^
  File "/opt/venv/lib/python3.11/site-packages/flask/templating.py", line 131, in _render
  File "/opt/venv/lib/python3.11/site-packages/flask/app.py", line 865, in dispatch_request
    rv = template.render(context)
    return self.ensure_sync(self.view_functions[rule.endpoint])(**view_args)  # type: ignore[no-any-return]
           ^^^^^^^^^^^^^^^^^^^^^^^^^^^^^^^^^^^^^^^^^^^^^^^^^^^^^^^^^^^^^^^^^
  File "/opt/venv/lib/python3.11/site-packages/flask_login/utils.py", line 290, in decorated_view
    return current_app.ensure_sync(func)(*args, **kwargs)
           ^^^^^^^^^^^^^^^^^^^^^^^^^^^^^^^^^^^^^^^^^^^^^^
  File "/app/photovault/routes/admin.py", line 38, in wrap
    return f(*args, **kwargs)
           ^^^^^^^^^^^^^^^^^^
         ^^^^^^^^^^^^^^^^^^^^^^^^
  File "/opt/venv/lib/python3.11/site-packages/jinja2/environment.py", line 1304, in render
    self.environment.handle_exception()
  File "/opt/venv/lib/python3.11/site-packages/jinja2/environment.py", line 939, in handle_exception
    raise rewrite_traceback_stack(source=source)
  File "/app/photovault/templates/admin/user_detail.html", line 15, in top-level template code
    {% extends "base.html" %}
  File "/app/photovault/templates/base.html", line 260, in top-level template code
    {% block content %}{% endblock %}
    ^^^^^^^^^^^^^^^^^^^^^^^^^
  File "/app/photovault/templates/admin/user_detail.html", line 161, in block 'content'
    {{ photo.original_filename[:20] }}{% if photo.original_filename|length > 20 %}...{% endif %}
    ^^^^^^^^^^^^^^^^^^^^^^^^^
jinja2.exceptions.UndefinedError: 'photovault.models.Photo object' has no attribute 'original_filename'