  File "/app/photovault/routes/auth.py", line 66, in find_user
    return User.query.filter(
           ^^^^
NameError: cannot access free variable 'User' where it is not associated with a value in enclosing scope
2025-10-20 16:14:40,914 ERROR: Exception on /auth/login [POST] [in /opt/venv/lib/python3.11/site-packages/flask/app.py:838]
Traceback (most recent call last):
  File "/opt/venv/lib/python3.11/site-packages/flask/app.py", line 1473, in wsgi_app
    response = self.full_dispatch_request()
               ^^^^^^^^^^^^^^^^^^^^^^^^^^^^
  File "/opt/venv/lib/python3.11/site-packages/flask/app.py", line 882, in full_dispatch_request
    rv = self.handle_user_exception(e)
         ^^^^^^^^^^^^^^^^^^^^^^^^^^^^^
  File "/opt/venv/lib/python3.11/site-packages/flask/app.py", line 880, in full_dispatch_request
    rv = self.dispatch_request()
         ^^^^^^^^^^^^^^^^^^^^^^^
  File "/opt/venv/lib/python3.11/site-packages/flask/app.py", line 865, in dispatch_request
    return self.ensure_sync(self.view_functions[rule.endpoint])(**view_args)  # type: ignore[no-any-return]
           ^^^^^^^^^^^^^^^^^^^^^^^^^^^^^^^^^^^^^^^^^^^^^^^^^^^^^^^^^^^^^^^^^
  File "/app/photovault/routes/auth.py", line 71, in login
    user = safe_db_query(find_user, operation_name="user lookup")
           ^^^^^^^^^^^^^^^^^^^^^^^^^^^^^^^^^^^^^^^^^^^^^^^^^^^^^^
  File "/app/photovault/utils/__init__.py", line 82, in safe_db_query
    return execute_query()
           ^^^^^^^^^^^^^^^
  File "/app/photovault/utils/__init__.py", line 68, in wrapper
    raise e
  File "/app/photovault/utils/__init__.py", line 28, in wrapper
    return func(*args, **kwargs)
           ^^^^^^^^^^^^^^^^^^^^^
  File "/app/photovault/utils/__init__.py", line 79, in execute_query
    return query_func()
           ^^^^^^^^^^^^
  File "/app/photovault/routes/auth.py", line 66, in find_user
    return User.query.filter(
           ^^^^
NameError: cannot access free variable 'User' where it is not associated with a value in enclosing scope
               ^^^^^^^^^^^^^^^^^^^^^^^^^^^^
  File "/opt/venv/lib/python3.11/site-packages/flask/app.py", line 882, in full_dispatch_request
    rv = self.handle_user_exception(e)
         ^^^^^^^^^^^^^^^^^^^^^^^^^^^^^
  File "/opt/venv/lib/python3.11/site-packages/flask/app.py", line 880, in full_dispatch_request
    rv = self.dispatch_request()
2025-10-20 16:14:40,914 ERROR: Exception on /auth/login [POST] [in /opt/venv/lib/python3.11/site-packages/flask/app.py:838]
         ^^^^^^^^^^^^^^^^^^^^^^^
Traceback (most recent call last):
  File "/opt/venv/lib/python3.11/site-packages/flask/app.py", line 865, in dispatch_request
  File "/opt/venv/lib/python3.11/site-packages/flask/app.py", line 1473, in wsgi_app
    return self.ensure_sync(self.view_functions[rule.endpoint])(**view_args)  # type: ignore[no-any-return]
    response = self.full_dispatch_request()
           ^^^^^^^^^^^^^^^^^^^^^^^^^^^^^^^^^^^^^^^^^^^^^^^^^^^^^^^^^^^^^^^^^
  File "/app/photovault/routes/auth.py", line 71, in login
    user = safe_db_query(find_user, operation_name="user lookup")
           ^^^^^^^^^^^^^^^^^^^^^^^^^^^^^^^^^^^^^^^^^^^^^^^^^^^^^^
  File "/app/photovault/utils/__init__.py", line 82, in safe_db_query
    return execute_query()
           ^^^^^^^^^^^^^^^
  File "/app/photovault/utils/__init__.py", line 68, in wrapper
    raise e
  File "/app/photovault/utils/__init__.py", line 28, in wrapper
    return func(*args, **kwargs)
           ^^^^^^^^^^^^^^^^^^^^^
  File "/app/photovault/utils/__init__.py", line 79, in execute_query
    return query_func()
           ^^^^^^^^^^^^
  File "/app/photovault/routes/auth.py", line 66, in find_user
    return User.query.filter(
           ^^^^
NameError: cannot access free variable 'User' where it is not associated with a value in enclosing scope
ERROR:photovault:Exception on /auth/login [POST]
Traceback (most recent call last):
  File "/opt/venv/lib/python3.11/site-packages/flask/app.py", line 1473, in wsgi_app
    response = self.full_dispatch_request()
               ^^^^^^^^^^^^^^^^^^^^^^^^^^^^
  File "/opt/venv/lib/python3.11/site-packages/flask/app.py", line 882, in full_dispatch_request
    rv = self.handle_user_exception(e)
    return query_func()
         ^^^^^^^^^^^^^^^^^^^^^^^^^^^^^
  File "/opt/venv/lib/python3.11/site-packages/flask/app.py", line 880, in full_dispatch_request
  File "/app/photovault/utils/__init__.py", line 68, in wrapper
  File "/app/photovault/routes/auth.py", line 71, in login
    rv = self.dispatch_request()
    user = safe_db_query(find_user, operation_name="user lookup")
    raise e
         ^^^^^^^^^^^^^^^^^^^^^^^
           ^^^^^^^^^^^^^^^^^^^^^^^^^^^^^^^^^^^^^^^^^^^^^^^^^^^^^^
  File "/opt/venv/lib/python3.11/site-packages/flask/app.py", line 865, in dispatch_request
  File "/app/photovault/utils/__init__.py", line 28, in wrapper
    return self.ensure_sync(self.view_functions[rule.endpoint])(**view_args)  # type: ignore[no-any-return]
  File "/app/photovault/utils/__init__.py", line 82, in safe_db_query
           ^^^^^^^^^^^^^^^^^^^^^^^^^^^^^^^^^^^^^^^^^^^^^^^^^^^^^^^^^^^^^^^^^
    return func(*args, **kwargs)
    return execute_query()
           ^^^^^^^^^^^^^^^
           ^^^^^^^^^^^^^^^^^^^^^
  File "/app/photovault/utils/__init__.py", line 79, in execute_query
           ^^^^^^^^^^^^
  File "/app/photovault/routes/auth.py", line 66, in find_user
    return User.query.filter(
           ^^^^
NameError: cannot access free variable 'User' where it is not associated with a value in enclosing scope